[2024-08-26 22:38:30,290] {taskinstance.py:1179} INFO - Dependencies all met for <TaskInstance: dag_con_conexion_postgres.insertar_en_tabla manual__2024-08-26T22:38:28.068490+00:00 [queued]>
[2024-08-26 22:38:30,294] {taskinstance.py:1179} INFO - Dependencies all met for <TaskInstance: dag_con_conexion_postgres.insertar_en_tabla manual__2024-08-26T22:38:28.068490+00:00 [queued]>
[2024-08-26 22:38:30,294] {taskinstance.py:1376} INFO - 
--------------------------------------------------------------------------------
[2024-08-26 22:38:30,295] {taskinstance.py:1377} INFO - Starting attempt 1 of 6
[2024-08-26 22:38:30,295] {taskinstance.py:1378} INFO - 
--------------------------------------------------------------------------------
[2024-08-26 22:38:30,301] {taskinstance.py:1397} INFO - Executing <Task(PostgresOperator): insertar_en_tabla> on 2024-08-26 22:38:28.068490+00:00
[2024-08-26 22:38:30,303] {standard_task_runner.py:52} INFO - Started process 251 to run task
[2024-08-26 22:38:30,305] {standard_task_runner.py:79} INFO - Running: ['***', 'tasks', 'run', 'dag_con_conexion_postgres', 'insertar_en_tabla', 'manual__2024-08-26T22:38:28.068490+00:00', '--job-id', '6', '--raw', '--subdir', 'DAGS_FOLDER/dag-postgres.py', '--cfg-path', '/tmp/tmpxia8sbbd', '--error-file', '/tmp/tmp_ozcq7rz']
[2024-08-26 22:38:30,306] {standard_task_runner.py:80} INFO - Job 6: Subtask insertar_en_tabla
[2024-08-26 22:38:30,334] {task_command.py:371} INFO - Running <TaskInstance: dag_con_conexion_postgres.insertar_en_tabla manual__2024-08-26T22:38:28.068490+00:00 [running]> on host 419b05bd8ee5
[2024-08-26 22:38:30,362] {taskinstance.py:1591} INFO - Exporting the following env vars:
AIRFLOW_CTX_DAG_OWNER=DavidBU
AIRFLOW_CTX_DAG_ID=dag_con_conexion_postgres
AIRFLOW_CTX_TASK_ID=insertar_en_tabla
AIRFLOW_CTX_EXECUTION_DATE=2024-08-26T22:38:28.068490+00:00
AIRFLOW_CTX_TRY_NUMBER=1
AIRFLOW_CTX_DAG_RUN_ID=manual__2024-08-26T22:38:28.068490+00:00
[2024-08-26 22:38:30,365] {base.py:68} INFO - Using connection ID 'postgres_localhost' for task execution.
[2024-08-26 22:38:30,370] {dbapi.py:231} INFO - Running statement: 
            insert into fin_mundo (dt,pais) values ('12-12-2025','Colombia');
            insert into fin_mundo (dt,pais) values ('15-08-2035','Brasil');
            insert into fin_mundo (dt,pais) values ('21-09-2030','Argentina');
            insert into fin_mundo (dt,pais) values ('13-07-2045','Chile');
            insert into fin_mundo (dt,pais) values ('17-11-2028','Ecuador');
            insert into fin_mundo (dt,pais) values ('19-03-2032','Peru');
            insert into fin_mundo (dt,pais) values ('18-08-2026','Uruguay');
            insert into fin_mundo (dt,pais) values ('22-05-2037','Paraguay');
            insert into fin_mundo (dt,pais) values ('12-12-2080','Venezuela');
            insert into fin_mundo (dt,pais) values ('12-12-2071','Mexico');
        , parameters: None
[2024-08-26 22:38:30,371] {taskinstance.py:1909} ERROR - Task failed with exception
Traceback (most recent call last):
  File "/home/airflow/.local/lib/python3.7/site-packages/airflow/providers/postgres/operators/postgres.py", line 92, in execute
    self.hook.run(self.sql, self.autocommit, parameters=self.parameters)
  File "/home/airflow/.local/lib/python3.7/site-packages/airflow/hooks/dbapi.py", line 211, in run
    self._run_command(cur, sql_statement, parameters)
  File "/home/airflow/.local/lib/python3.7/site-packages/airflow/hooks/dbapi.py", line 235, in _run_command
    cur.execute(sql_statement)
psycopg2.errors.DatetimeFieldOverflow: date/time field value out of range: "15-08-2035"
LINE 3: ...          insert into fin_mundo (dt,pais) values ('15-08-203...
                                                             ^
HINT:  Perhaps you need a different "datestyle" setting.

[2024-08-26 22:38:30,375] {taskinstance.py:1420} INFO - Marking task as UP_FOR_RETRY. dag_id=dag_con_conexion_postgres, task_id=insertar_en_tabla, execution_date=20240826T223828, start_date=20240826T223830, end_date=20240826T223830
[2024-08-26 22:38:30,380] {standard_task_runner.py:97} ERROR - Failed to execute job 6 for task insertar_en_tabla (date/time field value out of range: "15-08-2035"
LINE 3: ...          insert into fin_mundo (dt,pais) values ('15-08-203...
                                                             ^
HINT:  Perhaps you need a different "datestyle" setting.
; 251)
[2024-08-26 22:38:30,403] {local_task_job.py:156} INFO - Task exited with return code 1
[2024-08-26 22:38:30,423] {local_task_job.py:273} INFO - 0 downstream tasks scheduled from follow-on schedule check
